<?xml version='1.0'?>
<sdf version='1.4'>
  <model name="ssmr">
    <static>false</static>

    <link name='chassis'>
      <pose>0 0 .1 0 0 0</pose>
      <inertial>
        <mass>14.0</mass>
        <inertia>
          <ixx>0.3</ixx>
          <ixy>0.0</ixy>
          <ixz>0.0</ixz>
          <iyy>0.3)</iyy>
          <iyz>0.0</iyz>
          <izz>0.3</izz>
        </inertia>
      </inertial>
      <collision name='collision'>
        <geometry>
          <box>
            <size>.4 .2 .1</size>
          </box>
        </geometry>
      </collision>

      <visual name='visual'>
        <geometry>
          <box>
            <size>.4 .2 .1</size>
          </box>
        </geometry>
        <transparency> 0.5 </transparency>
      </visual>

      <!-- <collision name='caster_collision'>
        <pose>-0.15 0 -0.05 0 0 0</pose>
        <geometry>
          <sphere>
            <radius>.05</radius>
          </sphere>
        </geometry>

        <surface>
          <friction>
            <ode>
              <mu>0</mu>
              <mu2>0</mu2>
              <slip1>1.0</slip1>
              <slip2>1.0</slip2>
            </ode>
          </friction>
        </surface>
      </collision>

      <visual name='caster_visual'>
        <pose>-0.15 0 -0.05 0 0 0</pose>
        <geometry>
          <sphere>
            <radius>.05</radius>
          </sphere>
        </geometry>
      </visual>-->
    </link>


    <link name="left_front_wheel">
      <pose>0.12 0.13 0.1 0 1.5707 1.5707</pose>
      <collision name="collision">
        <geometry>
          <cylinder>
            <radius>.1</radius>
            <length>.05</length>
          </cylinder>
        </geometry>
        <surface>
          <friction>
            <ode>
              <mu>0.1</mu>
              <mu2>0.5</mu2>
              <!-- <slip1>1.0</slip1>
              <slip2>1.0</slip2> -->
            </ode>
          </friction>
        </surface>
      </collision>
      <visual name="visual">
        <geometry>
          <cylinder>
            <radius>.1</radius>
            <length>.05</length>
          </cylinder>
        </geometry>
        <transparency> 0.5 </transparency>
      </visual>
    </link>

    <link name="right_front_wheel">
      <pose>0.12 -0.13 0.1 0 1.5707 1.5707</pose>
      <collision name="collision">
        <geometry>
          <cylinder>
            <radius>.1</radius>
            <length>.05</length>
          </cylinder>
        </geometry>
        <surface>
          <friction>
            <ode>
              <mu>0.1</mu>
              <mu2>0.5</mu2>
              <!-- <slip1>1.0</slip1>
              <slip2>1.0</slip2> -->
            </ode>
          </friction>
        </surface>
      </collision>
      <visual name="visual">
        <geometry>
          <cylinder>
            <radius>.1</radius>
            <length>.05</length>
          </cylinder>
        </geometry>
        <transparency> 0.5 </transparency>
      </visual>
    </link>

    <joint type="revolute" name="left_front_wheel_hinge">
      <pose>0 0 -0.03 0 0 0</pose>
      <child>left_front_wheel</child>
      <parent>chassis</parent>
      <axis>
        <xyz>0 1 0</xyz>
      </axis>
    </joint>

    <joint type="revolute" name="right_front_wheel_hinge">
      <pose>0 0 0.03 0 0 0</pose>
      <child>right_front_wheel</child>
      <parent>chassis</parent>
      <axis>
        <xyz>0 1 0</xyz>
      </axis>
    </joint>

    <link name="left_rear_wheel">
      <pose>-0.12 0.13 0.1 0 1.5707 1.5707</pose>
      <collision name="collision">
        <geometry>
          <cylinder>
            <radius>.1</radius>
            <length>.05</length>
          </cylinder>
        </geometry>
        <surface>
          <friction>
            <ode>
              <mu>0.1</mu>
              <mu2>0.5</mu2>
              <!-- <slip1>1.0</slip1>
              <slip2>1.0</slip2> -->
            </ode>
          </friction>
        </surface>
      </collision>
      <visual name="visual">
        <geometry>
          <cylinder>
            <radius>.1</radius>
            <length>.05</length>
          </cylinder>
        </geometry>
        <transparency> 0.5 </transparency>
      </visual>
    </link>

    <link name="right_rear_wheel">
      <pose>-0.12 -0.13 0.1 0 1.5707 1.5707</pose>
      <collision name="collision">
        <geometry>
          <cylinder>
            <radius>.1</radius>
            <length>.05</length>
          </cylinder>
        </geometry>
        <surface>
          <friction>
            <ode>
              <mu>0.1</mu>
              <mu2>0.5</mu2>
              <!-- <slip1>1.0</slip1>
              <slip2>1.0</slip2> -->
            </ode>
          </friction>
        </surface>
      </collision>
      <visual name="visual">
        <geometry>
          <cylinder>
            <radius>.1</radius>
            <length>.05</length>
          </cylinder>
        </geometry>
        <transparency> 0.5 </transparency>
      </visual>
    </link>

    <joint type="revolute" name="left_rear_wheel_hinge">
      <pose>0 0 -0.03 0 0 0</pose>
      <child>left_rear_wheel</child>
      <parent>chassis</parent>
      <axis>
        <xyz>0 1 0</xyz>
      </axis>
    </joint>

    <joint type="revolute" name="right_rear_wheel_hinge">
      <pose>0 0 0.03 0 0 0</pose>
      <child>right_rear_wheel</child>
      <parent>chassis</parent>
      <axis>
        <xyz>0 1 0</xyz>
      </axis>
    </joint>

  </model>
</sdf>